{"uid":"854391b993f0aa53","name":"test_add_to_cart_item","fullName":"tests.test_glebk#test_add_to_cart_item","historyId":"6ed356662411248603a23fb6518578f7","time":{"start":1747625952554,"stop":1747625952755,"duration":201},"status":"broken","statusMessage":"selenium.common.exceptions.SessionNotCreatedException: Message: session not created: probably user data directory is already in use, please specify a unique value for --user-data-dir argument, or don't use --user-data-dir\nStacktrace:\n#0 0x558e6057078a <unknown>\n#1 0x558e600130a0 <unknown>\n#2 0x558e6004d1ff <unknown>\n#3 0x558e60048c0f <unknown>\n#4 0x558e60098d75 <unknown>\n#5 0x558e60098296 <unknown>\n#6 0x558e6008a173 <unknown>\n#7 0x558e60056d4b <unknown>\n#8 0x558e600579b1 <unknown>\n#9 0x558e6053593b <unknown>\n#10 0x558e6053983a <unknown>\n#11 0x558e6051d692 <unknown>\n#12 0x558e6053a3c4 <unknown>\n#13 0x558e605024cf <unknown>\n#14 0x558e6055e568 <unknown>\n#15 0x558e6055e746 <unknown>\n#16 0x558e6056f5f6 <unknown>\n#17 0x7fdcf3a9caa4 <unknown>\n#18 0x7fdcf3b29c3c <unknown>","statusTrace":"tests/test_glebk.py:6: in test_add_to_cart_item\n    driver = webdriver.Chrome()\n/opt/hostedtoolcache/Python/3.12.10/x64/lib/python3.12/site-packages/selenium/webdriver/chrome/webdriver.py:45: in __init__\n    super().__init__(\n/opt/hostedtoolcache/Python/3.12.10/x64/lib/python3.12/site-packages/selenium/webdriver/chromium/webdriver.py:66: in __init__\n    super().__init__(command_executor=executor, options=options)\n/opt/hostedtoolcache/Python/3.12.10/x64/lib/python3.12/site-packages/selenium/webdriver/remote/webdriver.py:250: in __init__\n    self.start_session(capabilities)\n/opt/hostedtoolcache/Python/3.12.10/x64/lib/python3.12/site-packages/selenium/webdriver/remote/webdriver.py:342: in start_session\n    response = self.execute(Command.NEW_SESSION, caps)[\"value\"]\n/opt/hostedtoolcache/Python/3.12.10/x64/lib/python3.12/site-packages/selenium/webdriver/remote/webdriver.py:429: in execute\n    self.error_handler.check_response(response)\n/opt/hostedtoolcache/Python/3.12.10/x64/lib/python3.12/site-packages/selenium/webdriver/remote/errorhandler.py:232: in check_response\n    raise exception_class(message, screen, stacktrace)\nE   selenium.common.exceptions.SessionNotCreatedException: Message: session not created: probably user data directory is already in use, please specify a unique value for --user-data-dir argument, or don't use --user-data-dir\nE   Stacktrace:\nE   #0 0x558e6057078a <unknown>\nE   #1 0x558e600130a0 <unknown>\nE   #2 0x558e6004d1ff <unknown>\nE   #3 0x558e60048c0f <unknown>\nE   #4 0x558e60098d75 <unknown>\nE   #5 0x558e60098296 <unknown>\nE   #6 0x558e6008a173 <unknown>\nE   #7 0x558e60056d4b <unknown>\nE   #8 0x558e600579b1 <unknown>\nE   #9 0x558e6053593b <unknown>\nE   #10 0x558e6053983a <unknown>\nE   #11 0x558e6051d692 <unknown>\nE   #12 0x558e6053a3c4 <unknown>\nE   #13 0x558e605024cf <unknown>\nE   #14 0x558e6055e568 <unknown>\nE   #15 0x558e6055e746 <unknown>\nE   #16 0x558e6056f5f6 <unknown>\nE   #17 0x7fdcf3a9caa4 <unknown>\nE   #18 0x7fdcf3b29c3c <unknown>","flaky":false,"newFailed":false,"newBroken":false,"newPassed":false,"retriesCount":0,"retriesStatusChange":false,"beforeStages":[{"name":"_session_faker","time":{"start":1747625652487,"stop":1747625652557,"duration":70},"status":"passed","steps":[],"attachments":[],"parameters":[],"shouldDisplayMessage":false,"stepsCount":0,"attachmentsCount":0,"hasContent":false,"attachmentStep":false},{"name":"config","time":{"start":1747625652557,"stop":1747625654375,"duration":1818},"status":"passed","steps":[],"attachments":[],"parameters":[],"shouldDisplayMessage":false,"stepsCount":0,"attachmentsCount":0,"hasContent":false,"attachmentStep":false},{"name":"jenkins_reset","time":{"start":1747625952358,"stop":1747625952553,"duration":195},"status":"passed","steps":[],"attachments":[],"parameters":[],"shouldDisplayMessage":false,"stepsCount":0,"attachmentsCount":0,"hasContent":false,"attachmentStep":false}],"testStage":{"status":"broken","statusMessage":"selenium.common.exceptions.SessionNotCreatedException: Message: session not created: probably user data directory is already in use, please specify a unique value for --user-data-dir argument, or don't use --user-data-dir\nStacktrace:\n#0 0x558e6057078a <unknown>\n#1 0x558e600130a0 <unknown>\n#2 0x558e6004d1ff <unknown>\n#3 0x558e60048c0f <unknown>\n#4 0x558e60098d75 <unknown>\n#5 0x558e60098296 <unknown>\n#6 0x558e6008a173 <unknown>\n#7 0x558e60056d4b <unknown>\n#8 0x558e600579b1 <unknown>\n#9 0x558e6053593b <unknown>\n#10 0x558e6053983a <unknown>\n#11 0x558e6051d692 <unknown>\n#12 0x558e6053a3c4 <unknown>\n#13 0x558e605024cf <unknown>\n#14 0x558e6055e568 <unknown>\n#15 0x558e6055e746 <unknown>\n#16 0x558e6056f5f6 <unknown>\n#17 0x7fdcf3a9caa4 <unknown>\n#18 0x7fdcf3b29c3c <unknown>","statusTrace":"tests/test_glebk.py:6: in test_add_to_cart_item\n    driver = webdriver.Chrome()\n/opt/hostedtoolcache/Python/3.12.10/x64/lib/python3.12/site-packages/selenium/webdriver/chrome/webdriver.py:45: in __init__\n    super().__init__(\n/opt/hostedtoolcache/Python/3.12.10/x64/lib/python3.12/site-packages/selenium/webdriver/chromium/webdriver.py:66: in __init__\n    super().__init__(command_executor=executor, options=options)\n/opt/hostedtoolcache/Python/3.12.10/x64/lib/python3.12/site-packages/selenium/webdriver/remote/webdriver.py:250: in __init__\n    self.start_session(capabilities)\n/opt/hostedtoolcache/Python/3.12.10/x64/lib/python3.12/site-packages/selenium/webdriver/remote/webdriver.py:342: in start_session\n    response = self.execute(Command.NEW_SESSION, caps)[\"value\"]\n/opt/hostedtoolcache/Python/3.12.10/x64/lib/python3.12/site-packages/selenium/webdriver/remote/webdriver.py:429: in execute\n    self.error_handler.check_response(response)\n/opt/hostedtoolcache/Python/3.12.10/x64/lib/python3.12/site-packages/selenium/webdriver/remote/errorhandler.py:232: in check_response\n    raise exception_class(message, screen, stacktrace)\nE   selenium.common.exceptions.SessionNotCreatedException: Message: session not created: probably user data directory is already in use, please specify a unique value for --user-data-dir argument, or don't use --user-data-dir\nE   Stacktrace:\nE   #0 0x558e6057078a <unknown>\nE   #1 0x558e600130a0 <unknown>\nE   #2 0x558e6004d1ff <unknown>\nE   #3 0x558e60048c0f <unknown>\nE   #4 0x558e60098d75 <unknown>\nE   #5 0x558e60098296 <unknown>\nE   #6 0x558e6008a173 <unknown>\nE   #7 0x558e60056d4b <unknown>\nE   #8 0x558e600579b1 <unknown>\nE   #9 0x558e6053593b <unknown>\nE   #10 0x558e6053983a <unknown>\nE   #11 0x558e6051d692 <unknown>\nE   #12 0x558e6053a3c4 <unknown>\nE   #13 0x558e605024cf <unknown>\nE   #14 0x558e6055e568 <unknown>\nE   #15 0x558e6055e746 <unknown>\nE   #16 0x558e6056f5f6 <unknown>\nE   #17 0x7fdcf3a9caa4 <unknown>\nE   #18 0x7fdcf3b29c3c <unknown>","steps":[],"attachments":[{"uid":"ebf90c45688acfe1","name":"log","source":"ebf90c45688acfe1.txt","type":"text/plain","size":3983}],"parameters":[],"shouldDisplayMessage":true,"stepsCount":0,"attachmentsCount":1,"hasContent":true,"attachmentStep":false},"afterStages":[],"labels":[{"name":"parentSuite","value":"tests"},{"name":"suite","value":"test_glebk"},{"name":"host","value":"fv-az1934-349"},{"name":"thread","value":"2689-MainThread"},{"name":"framework","value":"pytest"},{"name":"language","value":"cpython3"},{"name":"package","value":"tests.test_glebk"},{"name":"resultFormat","value":"allure2"}],"parameters":[],"links":[],"hidden":false,"retry":false,"extra":{"severity":"normal","retries":[],"categories":[{"name":"Test defects","matchedStatuses":[],"flaky":false}],"tags":[]},"source":"854391b993f0aa53.json","parameterValues":[]}